<?xml version="1.0"?>
<robot xmlns:xacro="http://www.ros.org/wiki/xacro" name="scout">

  <link name="base_link"/>

  <link name="front_left_wheel"/>

  <link name="rear_left_wheel"/>

  <link name="front_right_wheel"/>

  <link name="rear_right_wheel"/>

  <joint name="front_left_wheel_joint" type="continuous">
    <parent link="base_link"/>
    <child link="front_left_wheel"/>
    <origin xyz="0.23 0.225 0.0875" rpy="0 0 0"/>
    <axis xyz="0 1 0" rpy="0 0 0"/>
  </joint>

  <joint name="rear_left_wheel_joint" type="continuous">
    <parent link="base_link"/>
    <child link="rear_left_wheel"/>
    <origin xyz="-0.23 0.225 0.0875" rpy="0 0 0"/>
    <axis xyz="0 1 0" rpy="0 0 0"/>
  </joint>

  <joint name="front_right_wheel_joint" type="continuous">
    <parent link="base_link"/>
    <child link="front_right_wheel"/>
    <origin xyz="0.23 -0.225 0.0875" rpy="0 0 0"/>
    <axis xyz="0 1 0" rpy="0 0 0"/>
  </joint>

  <joint name="rear_right_wheel_joint" type="continuous">
    <parent link="base_link"/>
    <child link="rear_right_wheel"/>
    <origin xyz="-0.23 -0.225 0.0875" rpy="0 0 0"/>
    <axis xyz="0 1 0" rpy="0 0 0"/>
  </joint>

  <link name="top_plate"/>

  <joint name="top_plate_joint" type="fixed">
    <parent link="base_link"/>
    <child link="top_plate"/>
    <origin xyz="0 0 0.2330" rpy="0 0 0"/>
  </joint>

  <link name="laser_link"/>

  <joint name="laser_joint" type="fixed">
    <parent link="top_plate"/>
    <child link="laser_link"/>
    <origin xyz="0.2 0 0.1" rpy="0 0 0"/>
  </joint>

  <link name="os1_sensor"/>
    <parent link="top_plate"/>
    <child link="os1_sensor"/>
    <origin xyz="0.215 0 0.122" rpy="0 0 0"/>
  </joint>

  <link name="os1_lidar"/>

  <joint name="os1_sensor_lidar_joint" type="fixed">
    <parent link="os1_sensor" />
    <child link="os1_lidar" />
    <origin xyz="0 0 0.03618" rpy="0 0 0" />
  </joint>

  <link name="os1_imu"/>

  <joint name="os1_sensor_imu_joint" type="fixed">
    <parent link="os1_sensor" />
    <child link="os1_imu" />
    <origin xyz="0.006253 -0.011775 0.007645" rpy="0 0 0" />
  </joint>

</robot>